Workbook
Name _Toc55818592: Menu!$C$5
Name _Toc55849021: '5.13'!$C$22
Name _Toc55849022: '5.13'!$C$29

Sheet Menu
B2: Planilha | C2: Descrição
B3: 5.1 | C3: Investimento Total
B4: 5.2 | C4: Capital de Giro
B5: 5.3 | C5: Investimentos Pré-operacionais
B6: 5.4 | C6: Investimento Total (Consolidado)
B7: 5.5 | C7: Estimativa de Faturamento Mensal
B8: 5.6 | C8: Estimativa do Custo Unitário de Matéria-Prima, Materiais Diretos e Terceirizações
B9: 5.7 | C9: Estimativa dos Custos de Comercialização
B10: 5.8 | C10: Apuração dos Custos dos Materiais Diretos
B11: 5.9 | C11: Estimativa dos Custos com Mão de Obra
B12: 5.10 | C12: Estimativa do Custo com Depreciação
B13: 5.11 | C13: Estimativa dos Custos Fixos Operacionais Mensais
... B16: 6.0 | C16: Construções de Cenários

Sheet 5.1
B2: 5.1. Investimento total - Estimativa dos investimentos fixos
B4: 1. | C4: Máquinas e equipamentos
C5: Descrição | D5: Qtde. | E5: Valor Unitário | F5: Total
B6: 1 | F6: =D6*E6 -> 0
B7: 2 | F7: =D7*E7 -> 0
B8: 3 | F8: =D8*E8 -> 0
B9: 4 | F9: =D9*E9 -> 0
B10: 5 | F10: =D10*E10 -> 0
B11: 6 | F11: =D11*E11 -> 0
E12: SubTotal | F12: =SUM(F6:F11) -> 0
B14: 2. | C14: Móveis e Utensílios
C15: Descrição | D15: Qtde. | E15: Valor Unitário | F15: Total
B16: 1 | F16: =D16*E16 -> 0
B17: 2 | F17: =D17*E17 -> 0
B18: 3 | F18: =D18*E18 -> 0
B19: 4 | F19: =D19*E19 -> 0
B20: 5 | F20: =D20*E20 -> 0
B21: 6 | F21: =D21*E21 -> 0
B22: 7 | F22: =D22*E22 -> 0
E23: SubTotal | F23: =SUM(F16:F22) -> 0
B25: 3. | C25: Veículos (Meios de Transporte)
C26: Descrição | D26: Qtde. | E26: Valor Unitário | F26: Total
B27: 1
B28: 2
B29: 3
B30: 4
B31: 5
B32: 6
E33: SubTotal | F33: =SUM(F27:F32) -> 0
E35: Total Geral | F35: =SUM(F12,F23,F33) -> 0

Sheet 5.2
B2: 5.2 Capital de "Giro"
B3: A - Estimativa do estoque inicial (MP e Insumos)
C4: Descrição | D4: Qtde. | E4: Valor Unitário | F4: Valor Total
B5: 1 | F5: =D5*E5 -> 0
B6: 2 | F6: =D6*E6 -> 0
B7: 3 | F7: =D7*E7 -> 0
B8: 4 | F8: =D8*E8 -> 0
E9: Total | F9: =SUM(F5:F8) -> 0
B11: B - Caixa Mínimo
B12: 1. Formas de Pagamento oferecer?
B13: Prazo médio das vendas (receita) | D13: (%) | E13: Número dias | F13: Média Ponderada
B14: A Vista | D14: 0.3 | E14: 0 | F14: =D14*E14 -> 0
B15: Crédito (30 dias) | D15: 0.35 | E15: 0 | F15: =D15*E15 -> 0
B16: Crédito (60 dias) | D16: 0.35 | E16: 0 | F16: =D16*E16 -> 0
B17: Faturado | D17: 0 | E17: 0 | F17: =D17*E17 -> 0
E18: Prazo Médio | F18: =SUM(F14:F17) -> 0
B20: 2. Prazo médio pagamento
B21: Prazo médio das vendas (receita) | D21: (%) | E21: Número dias | F21: Média Ponderada
B22: A Vista | D22: 0.3 | E22: 0 | F22: =D22*E22 -> 0
B23: Crédito (30 dias) | D23: 0.35 | E23: 0 | F23: =D23*E23 -> 0
B24: Crédito ( 60 dias) | D24: 0.35 | E24: 0 | F24: =D24*E24 -> 0
B25: Faturado | D25: 0 | E25: 0 | F25: =D25*E25 -> 0
E26: Prazo Médio | F26: =SUM(F22:F25) -> 0
B28: 3. Necessidade média de Estoques
F29: Número de Dias
B30: Necessidade média de estoques | F30: 0
B33: 4. Cálculo da necessidade líquida de capital de giro em dias
B34: Recursos fora do seu caixa | F34: Número de Dias
B35: 1. Contas a receber - prazo médio vendas | F35: =F18 -> 0
B36: 2. Estoques | F36: =F30 -> 0
B37: Subtotal | F37: =SUM(F35:F36) -> 0
B39: Recursos de terceiros no caixa da empresa | F39: Número de Dias
B40: 3. Fornecedores - prazo médio compras | F40: =F26 -> 0
B41: Subtotal | F41: =F40 -> 0
B43: Necessidade Líquida | F43: =F37-F41 -> 0
B46: B - Caixa Mínimo
B47: 1. Custo Fixo Mensal (Despesas Fixas Mensais) | F47: ='5.11'!C21 -> 0
B48: 2. Custo Variável Mensal | F48: ='5.12'!C9 -> 0
B49: 3. Custo total da empresa | F49: =SUM(F47:F48) -> 0
B50: 4. Custo total diário | F50: =F49/30 -> 0
...

Sheet 5.3
B2: 5.3 Investimentos Pré-operacionais
B3: Investimentos Pré-Operacional | C3: R$
B4: Despesas de legalização | C4: 0
B5: Obras civis e/ou reformas | C5: 0
B6: Divulgação | C6: 0
B7: Cursos e Treinamentos | C7: 0
B8: Outras Despesas | C8: 0
B9: Total | C9: =SUM(C4:C8) -> 0

Sheet 5.4
B2: 5.4 Investimento Total
B3: Descrição dos investimentos | C3: Valor (R$) | D3: (%)
B4: 1. Investimentos Fixos | C4: ='5.1'!F35 -> 0 | D4: =IFERROR(C4/$C$7,0) -> 0
B5: 2. Capital de Giro | C5: ='5.2'!F58 -> 0 | D5: =IFERROR(C5/$C$7,0) -> 0
B6: 3. Investimentos Pré-operacionais | C6: ='5.3'!C9 -> 0 | D6: =IFERROR(C6/$C$7,0) -> 0
B7: Total | C7: =SUM(C4:C6) -> 0 | D7: 1
B9: Fontes dos recursos | C9: Valor (R$) | D9: (%)
B10: 1. Recursos Próprios | C10: 0 | D10: =IFERROR(C10/$C$7,0) -> 0
B11: 2. Recursos de Terceiros | C11: 0 | D11: =IFERROR(C11/$C$7,0) -> 0
B12: 3. Outros (BNDES) | C12: 0 | D12: =IFERROR(C12/$C$7,0) -> 0
B13: Total de Recursos | C13: =SUM(C10:C12) -> 0 | D13: =IFERROR(C13/$C$7,0) -> 0

Sheet 5.5
B2: 5.5 Estimativa de Faturamento Mensal
C3: Descrição | D3: Qtde Mensal. | E3: Valor Unitário | F3: Valor Total
B4: 1 | F4: =D4*E4 -> 0
B5: 2 | F5: =D5*E5 -> 0
B6: 3 | F6: =D6*E6 -> 0
B7: 4 | F7: =D7*E7 -> 0
B8: 5 | F8: =D8*E8 -> 0
B9: 6 | F9: =D9*E9 -> 0
B10: 7 | F10: =D10*E10 -> 0
E11: Total | F11: =SUM(F4:F10) -> 0

Sheet 5.6
B2: 5.6 Estimativa do Custo Unitário de Matéria-Prima, Materiais Diretos e Terceirizações
B3: Produto: 1
C4: Ingrediente | D4: Qtde | E4: Valor Unitário | F4: Valor Total
B5: 1 | F5: =D5*E5 -> 0
B6: 2 | F6: =D6*E6 -> 0
B7: 3 | F7: =D7*E7 -> 0
B8: 4 | F8: =D8*E8 -> 0
B9: 5 | F9: =D9*E9 -> 0
B10: 6 | F10: =D10*E10 -> 0
E11: Custo Total | F11: =SUM(F5:F10) -> 0
B14: Produto: 2
C15: Ingrediente | D15: Qtde | E15: Valor Unitário | F15: Valor Total
B16: 1 | F16: =D16*E16 -> 0
B17: 2 | F17: =D17*E17 -> 0
B18: 3 | F18: =D18*E18 -> 0
B19: 4 | F19: =D19*E19 -> 0
B20: 5 | F20: =D20*E20 -> 0
B21: 6 | F21: =D21*E21 -> 0
E22: Custo Total | F22: =SUM(F16:F21) -> 0

Sheet 5.7
B2: 5.7 Estimativa dos Custos de Comercialização
B3: Descrição | C3: % | D3: Faturamento Estimado | E3: Custo Total (R$) | H3: Tributação do Simples Nacional
B4: 1. Impostos | H4: Faixa | I4: Alíquota | J4: Valor a Deduzir (em R$) | K4: Receita Bruta anual (em R$)
B5: Impostos Federais | H5: 1ª Faixa | I5: 0.04 | J5: 0 | K5: Até 180.000,00
B6: SIMPLES | D6: ='5.5'!F11 -> 0 | H6: 2ª Faixa | I6: 0.073 | J6: 5940 | K6: De 180.000,01 a 360.000,00
B7: IRPJ (lucro) | H7: 3ª Faixa | I7: 0.095 | J7: 13860 | K7: De 360.000,01 a 720.000,00
B8: PIS | H8: 4ª Faixa | I8: 0.107 | J8: 22500 | K8: De 720.000,01 a 1.800.000,00
B9: COFINS | H9: 5ª Faixa | I9: 0.143 | J9: 87300 | K9: De 1.800.000,01 a 3.600.000,00
B10: CSLL | H10: 6ª Faixa | I10: 0.19 | J10: 378000 | K10: De 3.600.000,01 a 4.800.000,00
B11: Impostos Estaduais (vendas intermunicipais)
B12: ICMS
B13: Impostos Municipais (prestação de serviços)
B14: ISS
B15: Subtotal 1 | E15: =SUM(E6:E10,E12,E14) -> 0
B16: 2. Gastos com vendas
B17: Comissões
B18: Propaganda
B19: Taxa de administração do cartão de crédito | C19: 0.05 | D19: ='5.5'!F11*SUM('5.2'!D23:D24) -> 0 | E19: =C19*D19 -> 0
B20: Subtotal 2 | E20: =SUM(E17:E19) -> 0
B21: TOTAL (Subtotal 1 + 2) | E21: =SUM(E15,E20) -> 0

Sheet 5.8
B2: 5.8 Apuração dos Custos dos Materiais Diretos
C3: Produto | D3: Estimativa de Vendas (m²) | E3: Custo Unitário | F3: CMD
B4: 1 | E4: ='5.6'!F11 -> 0 | F4: =D4*E4 -> 0
B5: 2 | E5: ='5.6'!F22 -> 0 | F5: =D5*E5 -> 0
B6: 3 | F6: =D6*E6 -> 0
B7: 4 | F7: =D7*E7 -> 0
B8: 5 | F8: =D8*E8 -> 0
B9: 6 | F9: =D9*E9 -> 0
B10: 7 | F10: =D10*E10 -> 0
E11: Custo Total | F11: =SUM(F4:F10) -> 0

Sheet 5.9
B2: 5.9 Estimativa dos Custos com Mão de Obra
C3: Função | D3: Nº de Funcionários | E3: Salário Mensal (R$) | F3: Encargos sociais (%) | G3: Encargos sociais (R$) | H3: Custo Total por Funcionário (R$)
B4: 1 | F4: 0.79 | G4: =E4*F4 -> 0 | H4: =E4+G4 -> 0
B5: 2 | G5: =E5*F5 -> 0 | H5: =E5+G5 -> 0
B6: 3 | G6: =E6*F6 -> 0 | H6: =E6+G6 -> 0
B7: 4 | G7: =E7*F7 -> 0 | H7: =E7+G7 -> 0
B8: 5 | G8: =E8*F8 -> 0 | H8: =E8+G8 -> 0
B9: 6 | G9: =E9*F9 -> 0 | H9: =E9+G9 -> 0
B10: 7 | G10: =E10*F10 -> 0 | H10: =E10+G10 -> 0
B11: 8 | G11: =E11*F11 -> 0 | H11: =E11+G11 -> 0
B12: 9 | G12: =E12*F12 -> 0 | H12: =E12+G12 -> 0
B13: 10 | G13: =E13*F13 -> 0 | H13: =E13+G13 -> 0
G14: Total | H14: =SUMPRODUCT(D4:D13,H4:H13) -> 0

Sheet 5.10
B2: 5.10 Estimativa do Custo com Depreciação
C3: Descrição | D3: Vida Útil | E3: Valor Total | F3: Depreciação anual | G3: Depreciação Mensal
B4: 1 | D4: 10 | F4: =E4/D4 -> 0 | G4: =F4/12 -> 0
B5: 2 | D5: 10 | F5: =E5/D5 -> 0 | G5: =F5/12 -> 0
B6: 3 | D6: 10 | F6: =E6/D6 -> 0 | G6: =F6/12 -> 0
B7: 4 | D7: 10 | F7: =E7/D7 -> 0 | G7: =F7/12 -> 0
B8: 5 | D8: 3 | F8: =E8/D8 -> 0 | G8: =F8/12 -> 0
B9: 6 | D9: 3 | F9: =E9/D9 -> 0 | G9: =F9/12 -> 0
B10: 7 | D10: 5 | F10: =E10/D10 -> 0 | G10: =F10/12 -> 0
B11: 8 | D11: 5 | F11: =E11/D11 -> 0 | G11: =F11/12 -> 0
B12: 9 | D12: 5 | F12: =E12/D12 -> 0 | G12: =F12/12 -> 0
B13: 10 | D13: 5 | F13: =E13/D13 -> 0 | G13: =F13/12 -> 0
B14: 11 | D14: 5 | F14: =E14/D14 -> 0 | G14: =F14/12 -> 0
B15: 12 | D15: 5 | F15: =E15/D15 -> 0 | G15: =F15/12 -> 0
B16: 13 | D16: 5 | F16: =E16/D16 -> 0 | G16: =F16/12 -> 0
E17: TOTAL | F17: =SUM(F4:F16) -> 0 | G17: =SUM(G4:G16) -> 0

Sheet 5.11
B2: 5.11 Estimativa dos Custos Fixos Operacionais Mensais
B3: Descrição | C3: Custo Total Mensal (R$)
B4: Aluguel
B5: Condomínio
B6: IPTU
B7: Água
B8: Energia elétrica
B9: Telefone
B10: Honorários do contador
B11: Pró-labore | D11: << Salário dos sócios
B12: Manutenção dos equipamentos
B13: Salários + encargos – quadro 5.9 | C13: ='5.9'!H14 -> 0
B14: Material de limpeza
B15: Material de escritório
B16: Combustível
B17: Taxas diversas
B18: Serviços de terceiros
B19: Depreciação – quadro 5.10 | C19: ='5.10'!G17 -> 0
B20: Outras despesas
B21: Total | C21: =SUM(C4:C20) -> 0

Sheet 5.12
B2: 5.12 Demonstrativo de Resultados
B3: Descrição | C3: (R$) | D3: %
B4: Receita Total com Vendas | C4: ='5.5'!F11 -> 0 | D4: 1
B5: Custos Variáveis Totais
B6: (-) Custos com materiais diretos | C6: ='5.8'!F11 -> 0 | D6: =IFERROR(C6/$C$9,0) -> 0
B7: (-) Impostos sobre vendas | C7: ='5.7'!E15 -> 0 | D7: =IFERROR(C7/$C$9,0) -> 0
B8: (-) Gastos com vendas | C8: ='5.7'!E20 -> 0 | D8: =IFERROR(C8/$C$9,0) -> 0
B9: Subtotal de Custos Variáveis Totais | C9: =SUM(C6:C8) -> 0 | D9: 1
B10: Margem de Contribuição | C10: =C4-C9 -> 0
B11: (-) Custos Fixos Totais | C11: ='5.11'!C21 -> 0
B12: Resultado Operacional | C12: =C10-C11 -> 0 | D12: =IFERROR(C12/C10,0) -> 0

Sheet 5.13
B2: 5.13 Indicadores de Viabilidade
C4: 5.13.1 Ponto de Equilíbrio
D11: IMC | E11: =IFERROR('5.12'!C10/'5.12'!C4,0) -> 0
D12: PE | E12: =IFERROR('5.12'!C11/E11,0) -> 0
D13: ="Para atingir o ponto de equilíbrio será necessário gerar R$ "&TEXT(E12,"0.000,00")&" em receita mensal." -> Para atingir o ponto de equilíbrio será necessário gerar R$ 0.000,00 em receita mensal.
C15: 5.13.2 Lucratividade
D19: Lucratividade | E19: =IFERROR('5.12'!C12/'5.12'!C4,0) -> 0
D20: ="A lucratividade é de "&TEXT(E19,"0,00%")&" ao mês" -> A lucratividade é de 0,00% ao mês
C22: 5.13.3 Rentabilidade
D26: Rentabilidade | E26: =IFERROR('5.12'!C12/'5.4'!C7,0) -> 0
D27: ="A rentabilidade é de "&TEXT(E26,"0,00%")&" ao mês e de "&TEXT(E26*12,"00,00%")&" ao ano" -> A rentabilidade é de 0,00% ao mês e de 00,00% ao ano
C29: 5.13.4 Prazo de Retorno do Investimento
D34: Prazo de Retorno do Investimento | G34: =IFERROR('5.4'!C7/'5.12'!C12,0) -> 0
D35: ="O prazo de retorno do investimento é de "&TEXT(G34,"0,00")&" meses ou de "&TEXT(G34/12,"0,00")&" anos" -> O prazo de retorno do investimento é de 0,00 meses ou de 0,00 anos

Sheet 6.0
B2: 6.0 Construções de Cenários
C3: Cenário Provável | E3: Cenário Pessimista | G3: Cenário Otimista
B4: Descrição | C4: (R$) | D4: % | E4: (R$) | F4: % | G4: (R$) | H4: %
B5: Receita Total com Vendas | C5: ='5.12'!C4 -> 0 | D5: ='5.12'!D4 -> 1
B6: Custos Variáveis Totais
B7: (-) Custos com materiais diretos | C7: ='5.12'!C6 -> 0 | D7: ='5.12'!D6 -> 0
B8: (-) Impostos sobre vendas | C8: ='5.12'!C7 -> 0 | D8: ='5.12'!D7 -> 0
B9: (-) Gastos com vendas | C9: ='5.12'!C8 -> 0 | D9: ='5.12'!D8 -> 0
B10: Subtotal de Custos Variáveis Totais | C10: ='5.12'!C9 -> 0 | D10: ='5.12'!D9 -> 1
B11: Margem de Contribuição | C11: ='5.12'!C10 -> 0 | D11: ='5.12'!D10 -> 0
B12: (-) Custos Fixos Totais | C12: ='5.12'!C11 -> 0 | D12: ='5.12'!D11 -> 0
B13: Resultado Operacional | C13: ='5.12'!C12 -> 0 | D13: ='5.12'!D12 -> 0
